Workbook

Sheet Total
A1: /Project
A2: /Metrics/Metric/@description | B2: /Metrics/Metric/@name | C2: /Metrics/Metric/@value | D2: /Packages/Package/@name | E2: /Packages/Package/#id | F2: /Packages/Package/Class/@name | G2: /Packages/Package/Class/#id | H2: /Packages/Package/Class/Class/@name | I2: /Packages/Package/Class/Class/#id | J2: /Packages/Package/Class/Class/Method/@name | K2: /Packages/Package/Class/Class/Method/#id | L2: /Packages/Package/Class/Class/Method/Metrics/Metric/@description | M2: /Packages/Package/Class/Class/Method/Metrics/Metric/@name | N2: /Packages/Package/Class/Class/Method/Metrics/Metric/@value | O2: /Packages/Package/Class/Class/Metrics/Metric/@description | P2: /Packages/Package/Class/Class/Metrics/Metric/@name | Q2: /Packages/Package/Class/Class/Metrics/Metric/@value | R2: /Packages/Package/Class/Method/@name | S2: /Packages/Package/Class/Method/#id | T2: /Packages/Package/Class/Method/Metrics/Metric/@description | U2: /Packages/Package/Class/Method/Metrics/Metric/@name | V2: /Packages/Package/Class/Method/Metrics/Metric/@value | W2: /Packages/Package/Class/Metrics/Metric/@description | X2: /Packages/Package/Class/Metrics/Metric/@name | Y2: /Packages/Package/Class/Metrics/Metric/@value | Z2: /Packages/Package/Metrics/Metric/@description | AA2: /Packages/Package/Metrics/Metric/@name | AB2: /Packages/Package/Metrics/Metric/@value
A3: Attribute Hiding Factor | B3: AHF | C3: 0
A4: Attribute Inheritance Factor | B4: AIF | C4: 0.0612
A5: Coupling Factor | B5: CF | C5: 0.4938
A6: Effectiveness | B6: Effectiveness | C6: 20017
A7: Extendibility | B7: Extendibility | C7: 2.43
A8: Flexibility | B8: Flexibility | C8: 39006
A9: Functionality | B9: Functionality | C9: 25489
A10: Halstead Difficulty | B10: PRHD | C10: 1005916
A11: Halstead Effort | B11: PRCHEF | C11: 24029969576
A12: Halstead Errors | B12: PRCHER | C12: 129838
A13: Halstead Length | B13: PRCHL | C13: 4254
A14: Halstead Vocabulary | B14: PRCHVC | C14: 1345
... A31: Understandability | B31: Understandability | C31: -35578
D32: battleship | E32: 1 | F32: Barge | G32: 1 | R32: Barge(Compass, IPosition) | S32: 1 | T32: Cognitive Complexity | U32: CCM | V32: 0
D33: battleship | E33: 1 | F33: Barge | G33: 1 | R33: Barge(Compass, IPosition) | S33: 1 | T33: Condition Nesting Depth | U33: CND | V33: 0
D34: battleship | E34: 1 | F34: Barge | G34: 1 | R34: Barge(Compass, IPosition) | S34: 1 | T34: Coupling Dispersion | U34: CDISP | V34: 0.6
D35: battleship | E35: 1 | F35: Barge | G35: 1 | R35: Barge(Compass, IPosition) | S35: 1 | T35: Coupling Intensity | U35: CINT | V35: 5
D36: battleship | E36: 1 | F36: Barge | G36: 1 | R36: Barge(Compass, IPosition) | S36: 1 | T36: Foreign Data Providers | U36: FDP | V36: 0
D37: battleship | E37: 1 | F37: Barge | G37: 1 | R37: Barge(Compass, IPosition) | S37: 1 | T37: Halstead Difficulty | U37: HD | V37: 6
D38: battleship | E38: 1 | F38: Barge | G38: 1 | R38: Barge(Compass, IPosition) | S38: 1 | T38: Halstead Effort | U38: HEF | V38: 3011369
D39: battleship | E39: 1 | F39: Barge | G39: 1 | R39: Barge(Compass, IPosition) | S39: 1 | T39: Halstead Errors | U39: HER | V39: 0.015
D40: battleship | E40: 1 | F40: Barge | G40: 1 | R40: Barge(Compass, IPosition) | S40: 1 | T40: Halstead Length | U40: HL | V40: 14
D41: battleship | E41: 1 | F41: Barge | G41: 1 | R41: Barge(Compass, IPosition) | S41: 1 | T41: Halstead Vocabulary | U41: HVC | V41: 12
D42: battleship | E42: 1 | F42: Barge | G42: 1 | R42: Barge(Compass, IPosition) | S42: 1 | T42: Halstead Volume | U42: HVL | V42: 501895
D43: battleship | E43: 1 | F43: Barge | G43: 1 | R43: Barge(Compass, IPosition) | S43: 1 | T43: Lines Of Code | U43: LOC | V43: 11
... D51: battleship | E51: 1 | F51: Barge | G51: 1 | R51: Barge(Compass, IPosition) | S51: 1 | T51: Number Of Parameters | U51: NOPM | V51: 2
D52: battleship | E52: 1 | F52: Barge | G52: 1 | W52: Access To Foreign Data | X52: ATFD | Y52: 1
D53: battleship | E53: 1 | F53: Barge | G53: 1 | W53: Cognitive Complexity | X53: CCC | Y53: 0
D54: battleship | E54: 1 | F54: Barge | G54: 1 | W54: Coupling Between Objects | X54: CBO | Y54: 5
D55: battleship | E55: 1 | F55: Barge | G55: 1 | W55: Data Abstraction Coupling | X55: DAC | Y55: 0
D56: battleship | E56: 1 | F56: Barge | G56: 1 | W56: Depth Of Inheritance Tree | X56: DIT | Y56: 2
D57: battleship | E57: 1 | F57: Barge | G57: 1 | W57: Halstead Difficulty | X57: CHD | Y57: 7.5
D58: battleship | E58: 1 | F58: Barge | G58: 1 | W58: Halstead Effort | X58: CHEF | Y58: 4854378
D59: battleship | E59: 1 | F59: Barge | G59: 1 | W59: Halstead Errors | X59: CHER | Y59: 0.0206
D60: battleship | E60: 1 | F60: Barge | G60: 1 | W60: Halstead Length | X60: CHL | Y60: 17
D61: battleship | E61: 1 | F61: Barge | G61: 1 | W61: Halstead Vocabulary | X61: CHVC | Y61: 14
D62: battleship | E62: 1 | F62: Barge | G62: 1 | W62: Halstead Volume | X62: CHVL | Y62: 64725
D63: battleship | E63: 1 | F63: Barge | G63: 1 | W63: Lack Of Cohesion Of Methods | X63: LCOM | Y63: 0
...

Sheet System
A1: /Project
A2: /Metrics/Metric/@description | B2: /Metrics/Metric/@name | C2: /Metrics/Metric/@value
A3: Attribute Hiding Factor | B3: AHF | C3: 0
A4: Attribute Inheritance Factor | B4: AIF | C4: 0.0612
A5: Coupling Factor | B5: CF | C5: 0.4938
A6: Effectiveness | B6: Effectiveness | C6: 20017
A7: Extendibility | B7: Extendibility | C7: 2.43
A8: Flexibility | B8: Flexibility | C8: 39006
A9: Functionality | B9: Functionality | C9: 25489
A10: Halstead Difficulty | B10: PRHD | C10: 1005916
A11: Halstead Effort | B11: PRCHEF | C11: 24029969576
A12: Halstead Errors | B12: PRCHER | C12: 129838
A13: Halstead Length | B13: PRCHL | C13: 4254
A14: Halstead Vocabulary | B14: PRCHVC | C14: 1345
... A31: Understandability | B31: Understandability | C31: -35578

Sheet Package
A2: /Packages/Package/@name | B2: /Packages/Package/#id | C2: /Packages/Package/Class/@name | D2: /Packages/Package/Class/#id
A32: battleship | B32: 1 | C32: Barge | D32: 1
A33: battleship | B33: 1 | C33: Barge | D33: 1
A34: battleship | B34: 1 | C34: Barge | D34: 1
A35: battleship | B35: 1 | C35: Barge | D35: 1
A36: battleship | B36: 1 | C36: Barge | D36: 1
A37: battleship | B37: 1 | C37: Barge | D37: 1
A38: battleship | B38: 1 | C38: Barge | D38: 1
A39: battleship | B39: 1 | C39: Barge | D39: 1
A40: battleship | B40: 1 | C40: Barge | D40: 1
A41: battleship | B41: 1 | C41: Barge | D41: 1
A42: battleship | B42: 1 | C42: Barge | D42: 1
A43: battleship | B43: 1 | C43: Barge | D43: 1
... A4051: battleship | B4051: 1 | C4051: Tasks | D4051: 19
A4052: battleship | B4052: 1
A4053: battleship | B4053: 1
A4054: battleship | B4054: 1
A4055: battleship | B4055: 1
A4056: battleship | B4056: 1
A4057: battleship | B4057: 1
A4058: battleship | B4058: 1
A4059: battleship | B4059: 1
A4060: battleship | B4060: 1
A4061: battleship | B4061: 1
A4062: battleship | B4062: 1
A4063: battleship | B4063: 1
... A4073: battleship | B4073: 1
A4074: restserver | B4074: 2 | C4074: AiShotStrategy | D4074: 20
A4075: restserver | B4075: 2 | C4075: AiShotStrategy | D4075: 20
A4076: restserver | B4076: 2 | C4076: AiShotStrategy | D4076: 20
A4077: restserver | B4077: 2 | C4077: AiShotStrategy | D4077: 20
A4078: restserver | B4078: 2 | C4078: AiShotStrategy | D4078: 20
A4079: restserver | B4079: 2 | C4079: AiShotStrategy | D4079: 20
A4080: restserver | B4080: 2 | C4080: AiShotStrategy | D4080: 20
A4081: restserver | B4081: 2 | C4081: AiShotStrategy | D4081: 20
A4082: restserver | B4082: 2 | C4082: AiShotStrategy | D4082: 20
A4083: restserver | B4083: 2 | C4083: AiShotStrategy | D4083: 20
A4084: restserver | B4084: 2 | C4084: AiShotStrategy | D4084: 20
A4085: restserver | B4085: 2 | C4085: AiShotStrategy | D4085: 20
... A4999: restserver | B4999: 2 | C4999: GameSession | D4999: 26
...

Sheet Class
A2: /Packages/Package/Class/Class/@name | B2: /Packages/Package/Class/Class/#id | C2: /Packages/Package/Class/Class/Method/@name | D2: /Packages/Package/Class/Class/Method/#id
A1493: ShotResult | B1493: 1 | C1493: ShotResult(boolean, boolean, IShip, boolean) | D1493: 1
A1494: ShotResult | B1494: 1 | C1494: ShotResult(boolean, boolean, IShip, boolean) | D1494: 1
A1495: ShotResult | B1495: 1 | C1495: ShotResult(boolean, boolean, IShip, boolean) | D1495: 1
A1496: ShotResult | B1496: 1 | C1496: ShotResult(boolean, boolean, IShip, boolean) | D1496: 1
A1497: ShotResult | B1497: 1 | C1497: ShotResult(boolean, boolean, IShip, boolean) | D1497: 1
A1498: ShotResult | B1498: 1 | C1498: ShotResult(boolean, boolean, IShip, boolean) | D1498: 1
A1499: ShotResult | B1499: 1 | C1499: ShotResult(boolean, boolean, IShip, boolean) | D1499: 1
A1500: ShotResult | B1500: 1 | C1500: ShotResult(boolean, boolean, IShip, boolean) | D1500: 1
A1501: ShotResult | B1501: 1 | C1501: ShotResult(boolean, boolean, IShip, boolean) | D1501: 1
A1502: ShotResult | B1502: 1 | C1502: ShotResult(boolean, boolean, IShip, boolean) | D1502: 1
A1503: ShotResult | B1503: 1 | C1503: ShotResult(boolean, boolean, IShip, boolean) | D1503: 1
A1504: ShotResult | B1504: 1 | C1504: ShotResult(boolean, boolean, IShip, boolean) | D1504: 1
... A1592: ShotResult | B1592: 1 | C1592: valid() | D1592: 5
A1593: ShotResult | B1593: 1
A1594: ShotResult | B1594: 1
A1595: ShotResult | B1595: 1
A1596: ShotResult | B1596: 1
A1597: ShotResult | B1597: 1
A1598: ShotResult | B1598: 1
A1599: ShotResult | B1599: 1
A1600: ShotResult | B1600: 1
A1601: ShotResult | B1601: 1
A1602: ShotResult | B1602: 1
A1603: ShotResult | B1603: 1
A1604: ShotResult | B1604: 1
... A1621: ShotResult | B1621: 1
A4301: ErrorResponse | B4301: 2 | C4301: ErrorResponse(String) | D4301: 6
A4302: ErrorResponse | B4302: 2 | C4302: ErrorResponse(String) | D4302: 6
A4303: ErrorResponse | B4303: 2 | C4303: ErrorResponse(String) | D4303: 6
A4304: ErrorResponse | B4304: 2 | C4304: ErrorResponse(String) | D4304: 6
A4305: ErrorResponse | B4305: 2 | C4305: ErrorResponse(String) | D4305: 6
A4306: ErrorResponse | B4306: 2 | C4306: ErrorResponse(String) | D4306: 6
A4307: ErrorResponse | B4307: 2 | C4307: ErrorResponse(String) | D4307: 6
A4308: ErrorResponse | B4308: 2 | C4308: ErrorResponse(String) | D4308: 6
A4309: ErrorResponse | B4309: 2 | C4309: ErrorResponse(String) | D4309: 6
A4310: ErrorResponse | B4310: 2 | C4310: ErrorResponse(String) | D4310: 6
A4311: ErrorResponse | B4311: 2 | C4311: ErrorResponse(String) | D4311: 6
A4312: ErrorResponse | B4312: 2 | C4312: ErrorResponse(String) | D4312: 6
... A4320: ErrorResponse | B4320: 2 | C4320: ErrorResponse(String) | D4320: 6
...

Sheet Method
A1: /Packages/Package/Class/Class/Method/Metrics/Metric/@description | B1: /Packages/Package/Class/Class/Method/Metrics/Metric/@name | C1: /Packages/Package/Class/Class/Method/Metrics/Metric/@value | D1: /Packages/Package/Class/Class/Metrics/Metric/@description | E1: /Packages/Package/Class/Class/Metrics/Metric/@name | F1: /Packages/Package/Class/Class/Metrics/Metric/@value | G1: /Packages/Package/Class/Method/@name | H1: /Packages/Package/Class/Method/#id | I1: /Packages/Package/Class/Method/Metrics/Metric/@description | J1: /Packages/Package/Class/Method/Metrics/Metric/@name | K1: /Packages/Package/Class/Method/Metrics/Metric/@value | L1: /Packages/Package/Class/Metrics/Metric/@description | M1: /Packages/Package/Class/Metrics/Metric/@name | N1: /Packages/Package/Class/Metrics/Metric/@value | O1: /Packages/Package/Metrics/Metric/@description | P1: /Packages/Package/Metrics/Metric/@name | Q1: /Packages/Package/Metrics/Metric/@value
G2: processEnemyFire(boolean) | H2: 117 | I2: McCabe Cyclomatic Complexity | J2: CC | K2: 37
G3: menu() | H3: 163 | I3: McCabe Cyclomatic Complexity | J3: CC | K3: 22
G4: computeShots(IGame) | H4: 169 | I4: McCabe Cyclomatic Complexity | J4: CC | K4: 19
G5: describe(IMove) | H5: 121 | I5: McCabe Cyclomatic Complexity | J5: CC | K5: 18
G6: receiveShots(String, ShotRequest) | H6: 178 | I6: McCabe Cyclomatic Complexity | J6: CC | K6: 12
G7: randomEnemyFire() | H7: 51 | I7: McCabe Cyclomatic Complexity | J7: CC | K7: 10
G8: getHitButNotSunkPositions(IGame, Set<IPosition>) | H8: 170 | I8: McCabe Cyclomatic Complexity | J8: CC | K8: 10
G9: Caravel(Compass, IPosition) | H9: 2 | I9: McCabe Cyclomatic Complexity | J9: CC | K9: 9
G10: Carrack(Compass, IPosition) | H10: 3 | I10: McCabe Cyclomatic Complexity | J10: CC | K10: 9
G11: Frigate(Compass, IPosition) | H11: 25 | I11: McCabe Cyclomatic Complexity | J11: CC | K11: 9
G12: sendShots(GameSession, List<IPosition>) | H12: 174 | I12: McCabe Cyclomatic Complexity | J12: CC | K12: 9
G13: readClassicPosition(Scanner) | H13: 165 | I13: McCabe Cyclomatic Complexity | J13: CC | K13: 8
... G1345: PdfExporter() | H1345: 119 | I1345: Halstead Difficulty | J1345: HD | K1345: 0
G1346: valueOf(String) | H1346: 9 | I1346: Halstead Effort | J1346: HEF | K1346: NaN
G1347: values() | H1347: 10 | I1347: Halstead Effort | J1347: HEF | K1347: NaN
G1348: getFloatingShips() | H1348: 55 | I1348: Halstead Effort | J1348: HEF | K1348: NaN
G1349: getShips() | H1349: 56 | I1349: Halstead Effort | J1349: HEF | K1349: NaN
G1350: getShipsLike(String) | H1350: 57 | I1350: Halstead Effort | J1350: HEF | K1350: NaN
G1351: getSunkShips() | H1351: 58 | I1351: Halstead Effort | J1351: HEF | K1351: NaN
G1352: shipAt(IPosition) | H1352: 60 | I1352: Halstead Effort | J1352: HEF | K1352: NaN
G1353: getAlienFleet() | H1353: 63 | I1353: Halstead Effort | J1353: HEF | K1353: NaN
G1354: getAlienMoves() | H1354: 64 | I1354: Halstead Effort | J1354: HEF | K1354: NaN
G1355: getMyFleet() | H1355: 67 | I1355: Halstead Effort | J1355: HEF | K1355: NaN
G1356: getMyMoves() | H1356: 68 | I1356: Halstead Effort | J1356: HEF | K1356: NaN
G1357: randomEnemyFire() | H1357: 75 | I1357: Halstead Effort | J1357: HEF | K1357: NaN
... G1368: getSize() | H1368: 103 | I1368: Halstead Effort | J1368: HEF | K1368: NaN
G1369: processEnemyFire(boolean) | H1369: 117 | I1369: Halstead Effort | J1369: HEF | K1369: 1846018791
G1370: menu() | H1370: 163 | I1370: Halstead Effort | J1370: HEF | K1370: 570775874
G1371: export(IGame, String) | H1371: 122 | I1371: Halstead Effort | J1371: HEF | K1371: 494372346
G1372: computeShots(IGame) | H1372: 169 | I1372: Halstead Effort | J1372: HEF | K1372: 357962555
G1373: sendShots(GameSession, List<IPosition>) | H1373: 174 | I1373: Halstead Effort | J1373: HEF | K1373: 327985712
G1374: describe(IMove) | H1374: 121 | I1374: Halstead Effort | J1374: HEF | K1374: 310929156
G1375: randomEnemyFire() | H1375: 51 | I1375: Halstead Effort | J1375: HEF | K1375: 290117968
G1376: receiveShots(String, ShotRequest) | H1376: 178 | I1376: Halstead Effort | J1376: HEF | K1376: 259109345
G1377: Caravel(Compass, IPosition) | H1377: 2 | I1377: Halstead Effort | J1377: HEF | K1377: 121983903
G1378: Carrack(Compass, IPosition) | H1378: 3 | I1378: Halstead Effort | J1378: HEF | K1378: 121983903
G1379: Frigate(Compass, IPosition) | H1379: 25 | I1379: Halstead Effort | J1379: HEF | K1379: 121983903
G1380: evaluateShots(List<IPosition>, IGame, GameSession) | H1380: 177 | I1380: Halstead Effort | J1380: HEF | K1380: 117611466
... G1537: PdfExporter() | H1537: 119 | I1537: Halstead Effort | J1537: HEF | K1537: 0
...

Sheet Method_norm
A1: ID | B1: Método | C1: CC | D1: LOC | E1: NOPM | F1: CC_norm | G1: LOC_norm | H1: NOPM_norm | I1: Soma
A2: 117 | B2: processEnemyFire(boolean) | C2: =SUMIFS(Method!$K$2:$K$3841,Method!$H$2:$H$3841,$A2,Method!$J$2:$J$3841,C$1) -> 37 | D2: =SUMIFS(Method!$K$2:$K$3841,Method!$H$2:$H$3841,$A2,Method!$J$2:$J$3841,D$1) -> 130 | E2: =SUMIFS(Method!$K$2:$K$3841,Method!$H$2:$H$3841,$A2,Method!$J$2:$J$3841,E$1) -> 1 | F2: =(C2-MIN(C$2:C$193))/(MAX(C$2:C$193)-MIN(C$2:C$193)) -> 1 | G2: =(D2-MIN(D$2:D$193))/(MAX(D$2:D$193)-MIN(D$2:D$193)) -> 1 | H2: =(E2-MIN(E$2:E$193))/(MAX(E$2:E$193)-MIN(E$2:E$193)) -> 0.25 | I2: =SUM(F2:H2) -> 2.25
A3: 46 | B3: printBoard(IFleet, List<IMove>, boolean, boolean) | C3: =SUMIFS(Method!$K$2:$K$3841,Method!$H$2:$H$3841,$A3,Method!$J$2:$J$3841,C$1) -> 5 | D3: =SUMIFS(Method!$K$2:$K$3841,Method!$H$2:$H$3841,$A3,Method!$J$2:$J$3841,D$1) -> 32 | E3: =SUMIFS(Method!$K$2:$K$3841,Method!$H$2:$H$3841,$A3,Method!$J$2:$J$3841,E$1) -> 4 | F3: =(C3-MIN(C$2:C$193))/(MAX(C$2:C$193)-MIN(C$2:C$193)) -> 0.11111111 | G3: =(D3-MIN(D$2:D$193))/(MAX(D$2:D$193)-MIN(D$2:D$193)) -> 0.24615385 | H3: =(E3-MIN(E$2:E$193))/(MAX(E$2:E$193)-MIN(E$2:E$193)) -> 1 | I3: =SUM(F3:H3) -> 1.357265
A4: 178 | B4: receiveShots(String, ShotRequest) | C4: =SUMIFS(Method!$K$2:$K$3841,Method!$H$2:$H$3841,$A4,Method!$J$2:$J$3841,C$1) -> 12 | D4: =SUMIFS(Method!$K$2:$K$3841,Method!$H$2:$H$3841,$A4,Method!$J$2:$J$3841,D$1) -> 60 | E4: =SUMIFS(Method!$K$2:$K$3841,Method!$H$2:$H$3841,$A4,Method!$J$2:$J$3841,E$1) -> 2 | F4: =(C4-MIN(C$2:C$193))/(MAX(C$2:C$193)-MIN(C$2:C$193)) -> 0.30555556 | G4: =(D4-MIN(D$2:D$193))/(MAX(D$2:D$193)-MIN(D$2:D$193)) -> 0.46153846 | H4: =(E4-MIN(E$2:E$193))/(MAX(E$2:E$193)-MIN(E$2:E$193)) -> 0.5 | I4: =SUM(F4:H4) -> 1.267094
A5: 174 | B5: sendShots(GameSession, List<IPosition>) | C5: =SUMIFS(Method!$K$2:$K$3841,Method!$H$2:$H$3841,$A5,Method!$J$2:$J$3841,C$1) -> 9 | D5: =SUMIFS(Method!$K$2:$K$3841,Method!$H$2:$H$3841,$A5,Method!$J$2:$J$3841,D$1) -> 62 | E5: =SUMIFS(Method!$K$2:$K$3841,Method!$H$2:$H$3841,$A5,Method!$J$2:$J$3841,E$1) -> 2 | F5: =(C5-MIN(C$2:C$193))/(MAX(C$2:C$193)-MIN(C$2:C$193)) -> 0.22222222 | G5: =(D5-MIN(D$2:D$193))/(MAX(D$2:D$193)-MIN(D$2:D$193)) -> 0.47692308 | H5: =(E5-MIN(E$2:E$193))/(MAX(E$2:E$193)-MIN(E$2:E$193)) -> 0.5 | I5: =SUM(F5:H5) -> 1.1991453
A6: 163 | B6: menu() | C6: =SUMIFS(Method!$K$2:$K$3841,Method!$H$2:$H$3841,$A6,Method!$J$2:$J$3841,C$1) -> 22 | D6: =SUMIFS(Method!$K$2:$K$3841,Method!$H$2:$H$3841,$A6,Method!$J$2:$J$3841,D$1) -> 80 | E6: =SUMIFS(Method!$K$2:$K$3841,Method!$H$2:$H$3841,$A6,Method!$J$2:$J$3841,E$1) -> 0 | F6: =(C6-MIN(C$2:C$193))/(MAX(C$2:C$193)-MIN(C$2:C$193)) -> 0.58333333 | G6: =(D6-MIN(D$2:D$193))/(MAX(D$2:D$193)-MIN(D$2:D$193)) -> 0.61538462 | H6: =(E6-MIN(E$2:E$193))/(MAX(E$2:E$193)-MIN(E$2:E$193)) -> 0 | I6: =SUM(F6:H6) -> 1.1987179
A7: 142 | B7: buildShip(String, Compass, Position) | C7: =SUMIFS(Method!$K$2:$K$3841,Method!$H$2:$H$3841,$A7,Method!$J$2:$J$3841,C$1) -> 7 | D7: =SUMIFS(Method!$K$2:$K$3841,Method!$H$2:$H$3841,$A7,Method!$J$2:$J$3841,D$1) -> 36 | E7: =SUMIFS(Method!$K$2:$K$3841,Method!$H$2:$H$3841,$A7,Method!$J$2:$J$3841,E$1) -> 3 | F7: =(C7-MIN(C$2:C$193))/(MAX(C$2:C$193)-MIN(C$2:C$193)) -> 0.16666667 | G7: =(D7-MIN(D$2:D$193))/(MAX(D$2:D$193)-MIN(D$2:D$193)) -> 0.27692308 | H7: =(E7-MIN(E$2:E$193))/(MAX(E$2:E$193)-MIN(E$2:E$193)) -> 0.75 | I7: =SUM(F7:H7) -> 1.1935897
A8: 177 | B8: evaluateShots(List<IPosition>, IGame, GameSession) | C8: =SUMIFS(Method!$K$2:$K$3841,Method!$H$2:$H$3841,$A8,Method!$J$2:$J$3841,C$1) -> 6 | D8: =SUMIFS(Method!$K$2:$K$3841,Method!$H$2:$H$3841,$A8,Method!$J$2:$J$3841,D$1) -> 38 | E8: =SUMIFS(Method!$K$2:$K$3841,Method!$H$2:$H$3841,$A8,Method!$J$2:$J$3841,E$1) -> 3 | F8: =(C8-MIN(C$2:C$193))/(MAX(C$2:C$193)-MIN(C$2:C$193)) -> 0.13888889 | G8: =(D8-MIN(D$2:D$193))/(MAX(D$2:D$193)-MIN(D$2:D$193)) -> 0.29230769 | H8: =(E8-MIN(E$2:E$193))/(MAX(E$2:E$193)-MIN(E$2:E$193)) -> 0.75 | I8: =SUM(F8:H8) -> 1.1811966
A9: 169 | B9: computeShots(IGame) | C9: =SUMIFS(Method!$K$2:$K$3841,Method!$H$2:$H$3841,$A9,Method!$J$2:$J$3841,C$1) -> 19 | D9: =SUMIFS(Method!$K$2:$K$3841,Method!$H$2:$H$3841,$A9,Method!$J$2:$J$3841,D$1) -> 55 | E9: =SUMIFS(Method!$K$2:$K$3841,Method!$H$2:$H$3841,$A9,Method!$J$2:$J$3841,E$1) -> 1 | F9: =(C9-MIN(C$2:C$193))/(MAX(C$2:C$193)-MIN(C$2:C$193)) -> 0.5 | G9: =(D9-MIN(D$2:D$193))/(MAX(D$2:D$193)-MIN(D$2:D$193)) -> 0.42307692 | H9: =(E9-MIN(E$2:E$193))/(MAX(E$2:E$193)-MIN(E$2:E$193)) -> 0.25 | I9: =SUM(F9:H9) -> 1.1730769
A10: 141 | B10: Ship(String, Compass, IPosition, int) | C10: =SUMIFS(Method!$K$2:$K$3841,Method!$H$2:$H$3841,$A10,Method!$J$2:$J$3841,C$1) -> 1 | D10: =SUMIFS(Method!$K$2:$K$3841,Method!$H$2:$H$3841,$A10,Method!$J$2:$J$3841,D$1) -> 19 | E10: =SUMIFS(Method!$K$2:$K$3841,Method!$H$2:$H$3841,$A10,Method!$J$2:$J$3841,E$1) -> 4 | F10: =(C10-MIN(C$2:C$193))/(MAX(C$2:C$193)-MIN(C$2:C$193)) -> 0 | G10: =(D10-MIN(D$2:D$193))/(MAX(D$2:D$193)-MIN(D$2:D$193)) -> 0.14615385 | H10: =(E10-MIN(E$2:E$193))/(MAX(E$2:E$193)-MIN(E$2:E$193)) -> 1 | I10: =SUM(F10:H10) -> 1.1461538
A11: 121 | B11: describe(IMove) | C11: =SUMIFS(Method!$K$2:$K$3841,Method!$H$2:$H$3841,$A11,Method!$J$2:$J$3841,C$1) -> 18 | D11: =SUMIFS(Method!$K$2:$K$3841,Method!$H$2:$H$3841,$A11,Method!$J$2:$J$3841,D$1) -> 38 | E11: =SUMIFS(Method!$K$2:$K$3841,Method!$H$2:$H$3841,$A11,Method!$J$2:$J$3841,E$1) -> 1 | F11: =(C11-MIN(C$2:C$193))/(MAX(C$2:C$193)-MIN(C$2:C$193)) -> 0.47222222 | G11: =(D11-MIN(D$2:D$193))/(MAX(D$2:D$193)-MIN(D$2:D$193)) -> 0.29230769 | H11: =(E11-MIN(E$2:E$193))/(MAX(E$2:E$193)-MIN(E$2:E$193)) -> 0.25 | I11: =SUM(F11:H11) -> 1.0145299
A12: 122 | B12: export(IGame, String) | C12: =SUMIFS(Method!$K$2:$K$3841,Method!$H$2:$H$3841,$A12,Method!$J$2:$J$3841,C$1) -> 4 | D12: =SUMIFS(Method!$K$2:$K$3841,Method!$H$2:$H$3841,$A12,Method!$J$2:$J$3841,D$1) -> 55 | E12: =SUMIFS(Method!$K$2:$K$3841,Method!$H$2:$H$3841,$A12,Method!$J$2:$J$3841,E$1) -> 2 | F12: =(C12-MIN(C$2:C$193))/(MAX(C$2:C$193)-MIN(C$2:C$193)) -> 0.083333333 | G12: =(D12-MIN(D$2:D$193))/(MAX(D$2:D$193)-MIN(D$2:D$193)) -> 0.42307692 | H12: =(E12-MIN(E$2:E$193))/(MAX(E$2:E$193)-MIN(E$2:E$193)) -> 0.5 | I12: =SUM(F12:H12) -> 1.0064103
A13: 173 | B13: recordAiMove(IGame, List<IPosition>, ShotResponse) | C13: =SUMIFS(Method!$K$2:$K$3841,Method!$H$2:$H$3841,$A13,Method!$J$2:$J$3841,C$1) -> 4 | D13: =SUMIFS(Method!$K$2:$K$3841,Method!$H$2:$H$3841,$A13,Method!$J$2:$J$3841,D$1) -> 20 | E13: =SUMIFS(Method!$K$2:$K$3841,Method!$H$2:$H$3841,$A13,Method!$J$2:$J$3841,E$1) -> 3 | F13: =(C13-MIN(C$2:C$193))/(MAX(C$2:C$193)-MIN(C$2:C$193)) -> 0.083333333 | G13: =(D13-MIN(D$2:D$193))/(MAX(D$2:D$193)-MIN(D$2:D$193)) -> 0.15384615 | H13: =(E13-MIN(E$2:E$193))/(MAX(E$2:E$193)-MIN(E$2:E$193)) -> 0.75 | I13: =SUM(F13:H13) -> 0.98717949
... A193: 109 | B193: stillFloating() | C193: =SUMIFS(Method!$K$2:$K$3841,Method!$H$2:$H$3841,$A193,Method!$J$2:$J$3841,C$1) -> 1 | D193: =SUMIFS(Method!$K$2:$K$3841,Method!$H$2:$H$3841,$A193,Method!$J$2:$J$3841,D$1) -> 0 | E193: =SUMIFS(Method!$K$2:$K$3841,Method!$H$2:$H$3841,$A193,Method!$J$2:$J$3841,E$1) -> 0 | F193: =(C193-MIN(C$2:C$193))/(MAX(C$2:C$193)-MIN(C$2:C$193)) -> 0 | G193: =(D193-MIN(D$2:D$193))/(MAX(D$2:D$193)-MIN(D$2:D$193)) -> 0 | H193: =(E193-MIN(E$2:E$193))/(MAX(E$2:E$193)-MIN(E$2:E$193)) -> 0 | I193: =SUM(F193:H193) -> 0
